// Treating errors as sync form:

// Unlike callbacks, treat errors with promises is a simple and easy way, besides stay readeble.
// Create a function to divide 2 numbers;
function dividirNumeros(num1, num2) {
  // In this if we throw a new error whether the second parameter were equal 0 cause numbers cant be divide by zero and this probably throw back an error;
  if (num2 == 0) throw new Error("N達o pode ser feito uma divis達o por zero");

  // Case everything went right, it runs this return divide the numbers;
  return num1 / num2;
}

// In this example it was been treating the error with try/catch;
try {
  // Case the response of the function run everything okay, it will run the follow line:
  const resultado = dividirNumeros(2, 1);
  // And bring a result:
  console.log(`resultado: ${resultado}`);
  // The catch will treate the error
} catch (e) {
  // And print in console the message error
  console.log(e.message);
}
// NOTICE: The error is only treated by convetion, it will never display to the user (or almost hehe). But is a good way to handle with errors;


// Treating errors as async form:
// As before is declared a function, and within the function is declared a new Promise
function dividirNumeros(num1, num2) {
  const promise = new Promise((resolve, reject) => {
    // if this promise for some reason be reject, it run the follow line calling the reject function;
    if (num2 == 0) reject(new Error("N達o pode ser feito uma divis達o por zero"));

    // If everything runs fine, the resolve function will back the divide result;
    const resultado = num1 / num2;
    resolve(resultado)
  });
  // Function returning the promise when called
  return promise;
}
// Handle with the promise to divide the numbers
dividirNumeros(2, 1)
  // If everything went right, then bring the results
  .then(result => console.log(`sucesso: ${result}`))
  // Case dont, catch the error and handle display a mensage
  .catch(err => console.log(`erro: ${err.message}`));


  // Using the callback hell now as promises:
  const fs = require('fs');

function readFilePromise (fileName) {
  return new Promise((resolve, reject) => {
    fs.readFile(fileName, (err, content) => {
      if (err) return reject(err);
      resolve(content);
    });
  });
}

readFilePromise('file1.txt') // The function promise that will read the file
  .then((content) => { // Case file 1 be read,
    console.log(`Lido file1.txt com ${content.byteLength} bytes`); // Write the result in console
    return readFilePromise('file2.txt'); // Call the function again, that return a new promise
  })
  .then(content => { // Case promise return by 'then' before be resolve,
    console.log(`Lido file2.txt com ${content.byteLength} bytes`); // write the resul in the console
    return readFilePromise('file3.txt'); // and called the function again, receiving a new promise
  })
  .then((content) => { // Case the read promise from 'file3.txt' be resolved,
    console.log(`Lido file3.txt com ${content.byteLength} bytes`); // log the result in the console
  })
  .catch((err) => { // Case any of the promises along the way be rejected
    console.log(`Erro ao ler arquivos: ${err.message}`); // Write the result in the console
  });